Workbook

Sheet Energy data 1990 - 2020
A1: country | B1: Year | C1: Region | D1: CO2 emissions from fuel combustion (MtCO2) | E1: Average CO2 emission factor (tCO2/toe) | F1: CO2 intensity at constant purchasing power parities (kCO2/$15p) | G1: Total energy production (Mtoe) | H1: Total energy consumption (Mtoe) | I1: Share of renewables in electricity production (%) | J1: Share of electricity in total final energy consumption (%) | K1: Oil products domestic consumption (Mt) | L1: Refined oil products production (Mt) | M1: Natural gas production (bcm) | N1: Natural gas domestic consumption (bcm) | O1: Energy intensity of GDP at constant purchasing power parities (koe/$15p) | P1: Electricity production (TWh) | Q1: Electricity domestic consumption (TWh) | R1: Coal and lignite domestic consumption (Mt) | S1: Share of wind and solar in electricity production (%) | T1: Crude oil production (Mt) | U1: Coal and lignite production (Mt) | V1: AVERAGE(4.1) | W1: SURPLUS(4.2)
A2: Algeria | B2: 1990 | C2: Arab States | D2: 52.981921 | E2: 2.3878553 | F2: 0.22888934 | G2: 100.11275 | H2: 22.188078 | I2: 0.78297181 | J2: 8.3765921 | K2: 8.08 | L2: 25.395 | M2: 45.684035 | N2: 14.301991 | O2: 0.095855614 | P2: 17.242 | Q2: 13.693 | R2: 0.94 | S2: 0 | T2: 57.85 | U2: 0 | V2: =IF(Energy_data_1990___2020[[#This Row],[CO2 emissions from fuel combustion (MtCO2)]]>Energy_data_1990___2020[[#Totals],[CO2 emissions from fuel combustion (MtCO2)]],"Above Average","") | W2: =SUM(Energy_data_1990___2020[[#This Row],[Coal and lignite production (Mt)]]-Energy_data_1990___2020[[#This Row],[Coal and lignite domestic consumption (Mt)]]) -> -0.94
A3: Algeria | B3: 1991 | C3: Arab States | D3: 57.149971 | E3: 2.4350265 | F3: 0.24989464 | G3: 102.58617 | H3: 23.469959 | I3: 1.5807931 | J3: 7.9947484 | K3: 8.45 | L3: 25.435 | M3: 49.531989 | N3: 15.312995 | O3: 0.10262502 | P3: 18.535 | Q3: 14.058 | R3: 1.171 | S3: 0 | T3: 57.076 | U3: 0 | V3: =IF(Energy_data_1990___2020[[#This Row],[CO2 emissions from fuel combustion (MtCO2)]]>Energy_data_1990___2020[[#Totals],[CO2 emissions from fuel combustion (MtCO2)]],"Above Average","") | W3: =SUM(Energy_data_1990___2020[[#This Row],[Coal and lignite production (Mt)]]-Energy_data_1990___2020[[#This Row],[Coal and lignite domestic consumption (Mt)]]) -> -1.171
A4: Algeria | B4: 1992 | C4: Arab States | D4: 57.26243 | E4: 2.383517 | F4: 0.24595911 | G4: 104.20591 | H4: 24.024343 | I4: 1.0229259 | J4: 8.4900684 | K4: 8.349 | L4: 25.459 | M4: 51.670011 | N4: 15.72701 | O4: 0.10319167 | P4: 19.454 | Q4: 15.13 | R4: 1.056 | S4: 0 | T4: 56.904 | U4: 0 | V4: =IF(Energy_data_1990___2020[[#This Row],[CO2 emissions from fuel combustion (MtCO2)]]>Energy_data_1990___2020[[#Totals],[CO2 emissions from fuel combustion (MtCO2)]],"Above Average","") | W4: =SUM(Energy_data_1990___2020[[#This Row],[Coal and lignite production (Mt)]]-Energy_data_1990___2020[[#This Row],[Coal and lignite domestic consumption (Mt)]]) -> -1.056
A5: Algeria | B5: 1993 | C5: Arab States | D5: 59.198702 | E5: 2.4553346 | F5: 0.25973031 | G5: 104.92875 | H5: 24.110238 | I5: 1.7091948 | J5: 8.291029 | K5: 8.39 | L5: 25.463 | M5: 52.385991 | N5: 16.596984 | O5: 0.10578204 | P5: 20.653 | Q5: 15.144 | R5: 1.015 | S5: 0 | T5: 56.995 | U5: 0 | V5: =IF(Energy_data_1990___2020[[#This Row],[CO2 emissions from fuel combustion (MtCO2)]]>Energy_data_1990___2020[[#Totals],[CO2 emissions from fuel combustion (MtCO2)]],"Above Average","") | W5: =SUM(Energy_data_1990___2020[[#This Row],[Coal and lignite production (Mt)]]-Energy_data_1990___2020[[#This Row],[Coal and lignite domestic consumption (Mt)]]) -> -1.015
A6: Algeria | B6: 1994 | C6: Arab States | D6: 56.347927 | E6: 2.4246486 | F6: 0.24946793 | G6: 100.6126 | H6: 23.239627 | I6: 0.78386929 | J6: 9.1706055 | K6: 7.562 | L6: 23.971 | M6: 48.20602 | N6: 16.117004 | O6: 0.10288828 | P6: 21.177 | Q6: 15.545 | R6: 0.943 | S6: 0 | T6: 56.312 | U6: 0 | V6: =IF(Energy_data_1990___2020[[#This Row],[CO2 emissions from fuel combustion (MtCO2)]]>Energy_data_1990___2020[[#Totals],[CO2 emissions from fuel combustion (MtCO2)]],"Above Average","") | W6: =SUM(Energy_data_1990___2020[[#This Row],[Coal and lignite production (Mt)]]-Energy_data_1990___2020[[#This Row],[Coal and lignite domestic consumption (Mt)]]) -> -0.943
A7: Algeria | B7: 1995 | C7: Arab States | D7: 56.828812 | E7: 2.343684 | F7: 0.24238628 | G7: 106.72167 | H7: 24.247643 | I7: 0.92150497 | J7: 9.5431575 | K7: 7.446 | L7: 24.632 | M7: 54.851055 | N7: 16.786992 | O7: 0.10342106 | P7: 20.944 | Q7: 16.102 | R7: 0.901 | S7: 0 | T7: 56.753 | U7: 0 | V7: =IF(Energy_data_1990___2020[[#This Row],[CO2 emissions from fuel combustion (MtCO2)]]>Energy_data_1990___2020[[#Totals],[CO2 emissions from fuel combustion (MtCO2)]],"Above Average","") | W7: =SUM(Energy_data_1990___2020[[#This Row],[Coal and lignite production (Mt)]]-Energy_data_1990___2020[[#This Row],[Coal and lignite domestic consumption (Mt)]]) -> -0.901
A8: Algeria | B8: 1996 | C8: Arab States | D8: 56.165721 | E8: 2.3922596 | F8: 0.23012302 | G8: 112.6593 | H8: 23.478104 | I8: 0.61624138 | J8: 10.084258 | K8: 7.224 | L8: 24.007 | M8: 58.187034 | N8: 16.721017 | O8: 0.096194834 | P8: 21.907 | Q8: 16.697 | R8: 0.659 | S8: 0 | T8: 59.684 | U8: 0 | V8: =IF(Energy_data_1990___2020[[#This Row],[CO2 emissions from fuel combustion (MtCO2)]]>Energy_data_1990___2020[[#Totals],[CO2 emissions from fuel combustion (MtCO2)]],"Above Average","") | W8: =SUM(Energy_data_1990___2020[[#This Row],[Coal and lignite production (Mt)]]-Energy_data_1990___2020[[#This Row],[Coal and lignite domestic consumption (Mt)]]) -> -0.659
A9: Algeria | B9: 1997 | C9: Arab States | D9: 58.074674 | E9: 2.4138632 | F9: 0.2353555 | G9: 121.64199 | H9: 24.058809 | I9: 0.32701112 | J9: 10.226817 | K9: 7.239 | L9: 26.374 | M9: 67.076077 | N9: 17.835995 | O9: 0.097501589 | P9: 22.935 | Q9: 17.123 | R9: 0.541 | S9: 0 | T9: 60.9 | U9: 0 | V9: =IF(Energy_data_1990___2020[[#This Row],[CO2 emissions from fuel combustion (MtCO2)]]>Energy_data_1990___2020[[#Totals],[CO2 emissions from fuel combustion (MtCO2)]],"Above Average","") | W9: =SUM(Energy_data_1990___2020[[#This Row],[Coal and lignite production (Mt)]]-Energy_data_1990___2020[[#This Row],[Coal and lignite domestic consumption (Mt)]]) -> -0.541
A10: Algeria | B10: 1998 | C10: Arab States | D10: 59.494429 | E10: 2.3894406 | F10: 0.22940936 | G10: 127.09352 | H10: 24.898894 | I10: 0.85114806 | J10: 10.561598 | K10: 7.305 | L10: 26.107 | M10: 71.711045 | N10: 18.350023 | O10: 0.096009653 | P10: 25.26 | Q10: 18.674 | R10: 0.837 | S10: 0 | T10: 62.228 | U10: 0 | V10: =IF(Energy_data_1990___2020[[#This Row],[CO2 emissions from fuel combustion (MtCO2)]]>Energy_data_1990___2020[[#Totals],[CO2 emissions from fuel combustion (MtCO2)]],"Above Average","") | W10: =SUM(Energy_data_1990___2020[[#This Row],[Coal and lignite production (Mt)]]-Energy_data_1990___2020[[#This Row],[Coal and lignite domestic consumption (Mt)]]) -> -0.837
A11: Algeria | B11: 1999 | C11: Arab States | D11: 63.247065 | E11: 2.3795649 | F11: 0.2363173 | G11: 136.98255 | H11: 26.579256 | I11: 0.75816993 | J11: 10.379344 | K11: 7.868 | L11: 28.431 | M11: 80.548087 | N11: 19.539015 | O11: 0.099311136 | P11: 26.775 | Q11: 19.991 | R11: 0.849 | S11: 0 | T11: 64.412 | U11: 0 | V11: =IF(Energy_data_1990___2020[[#This Row],[CO2 emissions from fuel combustion (MtCO2)]]>Energy_data_1990___2020[[#Totals],[CO2 emissions from fuel combustion (MtCO2)]],"Above Average","") | W11: =SUM(Energy_data_1990___2020[[#This Row],[Coal and lignite production (Mt)]]-Energy_data_1990___2020[[#This Row],[Coal and lignite domestic consumption (Mt)]]) -> -0.849
A12: Algeria | B12: 2000 | C12: Arab States | D12: 64.229802 | E12: 2.3789766 | F12: 0.23120348 | G12: 142.22826 | H12: 26.998921 | I12: 0.19575147 | J12: 10.651919 | K12: 8.258 | L12: 29.27 | M12: 82.131946 | N12: 19.592006 | O12: 0.097186108 | P12: 27.586 | Q12: 21.211 | R12: 0.773 | S12: 0 | T12: 68.002 | U12: 0 | V12: =IF(Energy_data_1990___2020[[#This Row],[CO2 emissions from fuel combustion (MtCO2)]]>Energy_data_1990___2020[[#Totals],[CO2 emissions from fuel combustion (MtCO2)]],"Above Average","") | W12: =SUM(Energy_data_1990___2020[[#This Row],[Coal and lignite production (Mt)]]-Energy_data_1990___2020[[#This Row],[Coal and lignite domestic consumption (Mt)]]) -> -0.773
A13: Algeria | B13: 2001 | C13: Arab States | D13: 65.741657 | E13: 2.4300362 | F13: 0.229753 | G13: 136.78301 | H13: 27.053777 | I13: 0.23955838 | J13: 11.093436 | K13: 8.394 | L13: 30.272 | M13: 77.266942 | N13: 20.14402 | O13: 0.094547154 | P13: 28.803 | Q13: 22.302 | R13: 0.794 | S13: 0 | T13: 66.739 | U13: 0 | V13: =IF(Energy_data_1990___2020[[#This Row],[CO2 emissions from fuel combustion (MtCO2)]]>Energy_data_1990___2020[[#Totals],[CO2 emissions from fuel combustion (MtCO2)]],"Above Average","") | W13: =SUM(Energy_data_1990___2020[[#This Row],[Coal and lignite production (Mt)]]-Energy_data_1990___2020[[#This Row],[Coal and lignite domestic consumption (Mt)]]) -> -0.794
... A590: Kazakhstan | B590: 2020 | C590: Asia & Pacific | D590: 206.21718 | E590: 2.939759 | F590: 0.41579337 | G590: 169.47872 | H590: 70.147648 | I590: 11.650857 | J590: 18.0779 | K590: 12.195486 | L590: 15.667013 | M590: 36.737287 | N590: 16.3163 | O590: 0.14143791 | P590: 110.04697 | Q590: 92.402213 | R590: 76.143938 | S590: 2.545526 | T590: 87.071197 | U590: 103.78675 | V590: =IF(Energy_data_1990___2020[[#This Row],[CO2 emissions from fuel combustion (MtCO2)]]>Energy_data_1990___2020[[#Totals],[CO2 emissions from fuel combustion (MtCO2)]],"Above Average","") | W590: =SUM(Energy_data_1990___2020[[#This Row],[Coal and lignite production (Mt)]]-Energy_data_1990___2020[[#This Row],[Coal and lignite domestic consumption (Mt)]]) -> 27.642814
A591: Kuwait | B591: 1990 | C591: Middle east | D591: 27.83656 | E591: 3.080057 | F591: 0.52351034 | G591: 50.373797 | H591: 9.0376769 | I591: 0 | J591: 20.888641 | K591: 3.8 | L591: 13.274 | M591: 4.0280029 | N591: 6.0279931 | O591: 0.16996775 | P591: 18.477 | Q591: 14.272 | S591: 0 | T591: 46.337 | V591: =IF(Energy_data_1990___2020[[#This Row],[CO2 emissions from fuel combustion (MtCO2)]]>Energy_data_1990___2020[[#Totals],[CO2 emissions from fuel combustion (MtCO2)]],"Above Average","") | W591: =SUM(Energy_data_1990___2020[[#This Row],[Coal and lignite production (Mt)]]-Energy_data_1990___2020[[#This Row],[Coal and lignite domestic consumption (Mt)]]) -> 0
A592: Kuwait | B592: 1991 | C592: Middle east | D592: 7.5977588 | E592: 2.8969966 | F592: 0.24221559 | G592: 10.048077 | H592: 2.6226329 | I592: 0 | J592: 32.287583 | K592: 1.949 | L592: 2.9 | M592: 0.83400034 | N592: 0.83400034 | O592: 0.083609205 | P592: 10.78 | Q592: 8.116 | S592: 0 | T592: 9.219 | V592: =IF(Energy_data_1990___2020[[#This Row],[CO2 emissions from fuel combustion (MtCO2)]]>Energy_data_1990___2020[[#Totals],[CO2 emissions from fuel combustion (MtCO2)]],"Above Average","") | W592: =SUM(Energy_data_1990___2020[[#This Row],[Coal and lignite production (Mt)]]-Energy_data_1990___2020[[#This Row],[Coal and lignite domestic consumption (Mt)]]) -> 0
A593: Kuwait | B593: 1992 | C593: Middle east | D593: 22.257547 | E593: 2.5439748 | F593: 0.38814708 | G593: 59.748161 | H593: 8.7491225 | I593: 0 | J593: 18.930416 | K593: 4.484 | L593: 17.155 | M593: 4.9080048 | N593: 4.9080048 | O593: 0.15257505 | P593: 16.885 | Q593: 13.196 | S593: 0 | T593: 54.859 | V593: =IF(Energy_data_1990___2020[[#This Row],[CO2 emissions from fuel combustion (MtCO2)]]>Energy_data_1990___2020[[#Totals],[CO2 emissions from fuel combustion (MtCO2)]],"Above Average","") | W593: =SUM(Energy_data_1990___2020[[#This Row],[Coal and lignite production (Mt)]]-Energy_data_1990___2020[[#This Row],[Coal and lignite domestic consumption (Mt)]]) -> 0
A594: Kuwait | B594: 1993 | C594: Middle east | D594: 28.627366 | E594: 2.3375474 | F594: 0.37258597 | G594: 106.54248 | H594: 12.246753 | I594: 0 | J594: 18.243905 | K594: 4.329 | L594: 23.745 | M594: 8.696008 | N594: 8.696008 | O594: 0.15939184 | P594: 20.178 | Q594: 16.074 | S594: 0 | T594: 97.868 | V594: =IF(Energy_data_1990___2020[[#This Row],[CO2 emissions from fuel combustion (MtCO2)]]>Energy_data_1990___2020[[#Totals],[CO2 emissions from fuel combustion (MtCO2)]],"Above Average","") | W594: =SUM(Energy_data_1990___2020[[#This Row],[Coal and lignite production (Mt)]]-Energy_data_1990___2020[[#This Row],[Coal and lignite domestic consumption (Mt)]]) -> 0
A595: Kuwait | B595: 1994 | C595: Middle east | D595: 33.13382 | E595: 2.3078478 | F595: 0.39768798 | G595: 113.89669 | H595: 14.357021 | I595: 0 | J595: 19.289163 | K595: 5.404 | L595: 38.958 | M595: 9.2779905 | N595: 9.2779905 | O595: 0.17231984 | P595: 22.802 | Q595: 17.601 | S595: 0 | T595: 104.638 | V595: =IF(Energy_data_1990___2020[[#This Row],[CO2 emissions from fuel combustion (MtCO2)]]>Energy_data_1990___2020[[#Totals],[CO2 emissions from fuel combustion (MtCO2)]],"Above Average","") | W595: =SUM(Energy_data_1990___2020[[#This Row],[Coal and lignite production (Mt)]]-Energy_data_1990___2020[[#This Row],[Coal and lignite domestic consumption (Mt)]]) -> 0
A596: Kuwait | B596: 1995 | C596: Middle east | D596: 33.067868 | E596: 2.2474757 | F596: 0.3785074 | G596: 114.8924 | H596: 14.713337 | I596: 0 | J596: 18.076519 | K596: 6.008 | L596: 42.566 | M596: 9.278 | N596: 9.278 | O596: 0.16841446 | P596: 23.724 | Q596: 17.656 | S596: 0 | T596: 105.616 | V596: =IF(Energy_data_1990___2020[[#This Row],[CO2 emissions from fuel combustion (MtCO2)]]>Energy_data_1990___2020[[#Totals],[CO2 emissions from fuel combustion (MtCO2)]],"Above Average","") | W596: =SUM(Energy_data_1990___2020[[#This Row],[Coal and lignite production (Mt)]]-Energy_data_1990___2020[[#This Row],[Coal and lignite domestic consumption (Mt)]]) -> 0
A597: Kuwait | B597: 1996 | C597: Middle east | D597: 32.19544 | E597: 2.2235659 | F597: 0.36630465 | G597: 115.20983 | H597: 14.479193 | I597: 0 | J597: 20.687198 | K597: 5.672 | L597: 41.05 | M597: 9.302 | N597: 9.302 | O597: 0.16473748 | P597: 25.475 | Q597: 18.933 | S597: 0 | T597: 105.909 | V597: =IF(Energy_data_1990___2020[[#This Row],[CO2 emissions from fuel combustion (MtCO2)]]>Energy_data_1990___2020[[#Totals],[CO2 emissions from fuel combustion (MtCO2)]],"Above Average","") | W597: =SUM(Energy_data_1990___2020[[#This Row],[Coal and lignite production (Mt)]]-Energy_data_1990___2020[[#This Row],[Coal and lignite domestic consumption (Mt)]]) -> 0
A598: Kuwait | B598: 1997 | C598: Middle east | D598: 33.284775 | E598: 2.2772816 | F598: 0.36955821 | G598: 115.13625 | H598: 14.616012 | I598: 0 | J598: 21.941762 | K598: 6.033 | L598: 45.668 | M598: 9.27 | N598: 9.27 | O598: 0.16228042 | P598: 26.724 | Q598: 19.92 | S598: 0 | T598: 105.862 | V598: =IF(Energy_data_1990___2020[[#This Row],[CO2 emissions from fuel combustion (MtCO2)]]>Energy_data_1990___2020[[#Totals],[CO2 emissions from fuel combustion (MtCO2)]],"Above Average","") | W598: =SUM(Energy_data_1990___2020[[#This Row],[Coal and lignite production (Mt)]]-Energy_data_1990___2020[[#This Row],[Coal and lignite domestic consumption (Mt)]]) -> 0
A599: Kuwait | B599: 1998 | C599: Middle east | D599: 39.296407 | E599: 2.3584163 | F599: 0.42089161 | G599: 117.42055 | H599: 16.662201 | I599: 0 | J599: 21.324355 | K599: 7.322 | L599: 44.356 | M599: 9.491 | N599: 9.491 | O599: 0.17846366 | P599: 29.984 | Q599: 22.455 | S599: 0 | T599: 107.933 | V599: =IF(Energy_data_1990___2020[[#This Row],[CO2 emissions from fuel combustion (MtCO2)]]>Energy_data_1990___2020[[#Totals],[CO2 emissions from fuel combustion (MtCO2)]],"Above Average","") | W599: =SUM(Energy_data_1990___2020[[#This Row],[Coal and lignite production (Mt)]]-Energy_data_1990___2020[[#This Row],[Coal and lignite domestic consumption (Mt)]]) -> 0
A600: Kuwait | B600: 1999 | C600: Middle east | D600: 43.256479 | E600: 2.4217545 | F600: 0.4717463 | G600: 107.67062 | H600: 17.861629 | I600: 0 | J600: 22.600764 | K600: 8.479 | L600: 46.93 | M600: 8.688 | N600: 8.688 | O600: 0.19479526 | P600: 31.576 | Q600: 23.489 | S600: 0 | T600: 98.982 | V600: =IF(Energy_data_1990___2020[[#This Row],[CO2 emissions from fuel combustion (MtCO2)]]>Energy_data_1990___2020[[#Totals],[CO2 emissions from fuel combustion (MtCO2)]],"Above Average","") | W600: =SUM(Energy_data_1990___2020[[#This Row],[Coal and lignite production (Mt)]]-Energy_data_1990___2020[[#This Row],[Coal and lignite domestic consumption (Mt)]]) -> 0
A601: Kuwait | B601: 2000 | C601: Middle east | D601: 46.557731 | E601: 2.5088197 | F601: 0.48498124 | G601: 114.23074 | H601: 18.557624 | I601: 0 | J601: 21.141247 | K601: 8.148 | L601: 38.685 | M601: 9.6 | N601: 9.6 | O601: 0.19331052 | P601: 32.323 | Q601: 23.907 | S601: 0 | T601: 104.706 | V601: =IF(Energy_data_1990___2020[[#This Row],[CO2 emissions from fuel combustion (MtCO2)]]>Energy_data_1990___2020[[#Totals],[CO2 emissions from fuel combustion (MtCO2)]],"Above Average","") | W601: =SUM(Energy_data_1990___2020[[#This Row],[Coal and lignite production (Mt)]]-Energy_data_1990___2020[[#This Row],[Coal and lignite domestic consumption (Mt)]]) -> 0
A602: Kuwait | B602: 2001 | C602: Middle east | D602: 50.479685 | E602: 2.5493238 | F602: 0.52471594 | G602: 111.91584 | H602: 19.801206 | I602: 0 | J602: 22.425767 | K602: 8.705 | L602: 34.436 | M602: 9.5 | N602: 9.5 | O602: 0.20582554 | P602: 34.299 | Q602: 25.5 | S602: 0 | T602: 102.508 | V602: =IF(Energy_data_1990___2020[[#This Row],[CO2 emissions from fuel combustion (MtCO2)]]>Energy_data_1990___2020[[#Totals],[CO2 emissions from fuel combustion (MtCO2)]],"Above Average","") | W602: =SUM(Energy_data_1990___2020[[#This Row],[Coal and lignite production (Mt)]]-Energy_data_1990___2020[[#This Row],[Coal and lignite domestic consumption (Mt)]]) -> 0
... A621: Kuwait | B621: 2020 | C621: Middle east | D621: 94.666804 | E621: 2.5217432 | F621: 0.57517312 | G621: 151.14835 | H621: 37.540223 | I621: 0.27176739 | J621: 22.736389 | K621: 15.382077 | L621: 33.14148 | M621: 21.290523 | N621: 27.456435 | O621: 0.22808552 | P621: 74.575 | Q621: 54.364664 | S621: 0.27176739 | T621: 131.59773 | V621: =IF(Energy_data_1990___2020[[#This Row],[CO2 emissions from fuel combustion (MtCO2)]]>Energy_data_1990___2020[[#Totals],[CO2 emissions from fuel combustion (MtCO2)]],"Above Average","") | W621: =SUM(Energy_data_1990___2020[[#This Row],[Coal and lignite production (Mt)]]-Energy_data_1990___2020[[#This Row],[Coal and lignite domestic consumption (Mt)]]) -> 0
A622: Malaysia | B622: 1990 | C622: Asia & Pacific | D622: 50.73806 | E622: 2.3919224 | F622: 0.27290635 | G622: 47.749219 | H622: 21.212252 | I622: 17.331422 | J622: 12.797935 | K622: 12.077 | L622: 10.086 | M622: 18.356009 | N622: 8.1840046 | O622: 0.11409499 | P622: 23.016 | Q622: 19.945 | R622: 2.104 | S622: 0 | T622: 30.029 | U622: 0.111 | V622: =IF(Energy_data_1990___2020[[#This Row],[CO2 emissions from fuel combustion (MtCO2)]]>Energy_data_1990___2020[[#Totals],[CO2 emissions from fuel combustion (MtCO2)]],"Above Average","") | W622: =SUM(Energy_data_1990___2020[[#This Row],[Coal and lignite production (Mt)]]-Energy_data_1990___2020[[#This Row],[Coal and lignite domestic consumption (Mt)]]) -> -1.993
A623: Malaysia | B623: 1991 | C623: Asia & Pacific | D623: 61.257305 | E623: 2.3289748 | F623: 0.30077606 | G623: 51.967603 | H623: 26.302262 | I623: 16.601386 | J623: 13.058862 | K623: 12.958 | L623: 10.228 | M623: 21.796977 | N623: 11.623 | O623: 0.12914526 | P623: 26.552 | Q623: 22.388 | R623: 2.478 | S623: 0 | T623: 31.219 | U623: 0.2 | V623: =IF(Energy_data_1990___2020[[#This Row],[CO2 emissions from fuel combustion (MtCO2)]]>Energy_data_1990___2020[[#Totals],[CO2 emissions from fuel combustion (MtCO2)]],"Above Average","") | W623: =SUM(Energy_data_1990___2020[[#This Row],[Coal and lignite production (Mt)]]-Energy_data_1990___2020[[#This Row],[Coal and lignite domestic consumption (Mt)]]) -> -2.278
A624: Malaysia | B624: 1992 | C624: Asia & Pacific | D624: 64.389769 | E624: 2.2153275 | F624: 0.29035795 | G624: 53.349421 | H624: 29.065576 | I624: 14.874314 | J624: 13.610032 | K624: 13.523 | L624: 9.526 | M624: 22.592002 | N624: 12.597003 | O624: 0.13106773 | P624: 29.319 | Q624: 25.795 | R624: 2.602 | S624: 0 | T624: 31.979 | U624: 0.084 | V624: =IF(Energy_data_1990___2020[[#This Row],[CO2 emissions from fuel combustion (MtCO2)]]>Energy_data_1990___2020[[#Totals],[CO2 emissions from fuel combustion (MtCO2)]],"Above Average","") | W624: =SUM(Energy_data_1990___2020[[#This Row],[Coal and lignite production (Mt)]]-Energy_data_1990___2020[[#This Row],[Coal and lignite domestic consumption (Mt)]]) -> -2.518
A625: Malaysia | B625: 1993 | C625: Asia & Pacific | D625: 70.17734 | E625: 2.2260323 | F625: 0.28796258 | G625: 55.444974 | H625: 31.525751 | I625: 14.027462 | J625: 13.802186 | K625: 14.643 | L625: 10.767 | M625: 24.58601 | N625: 12.095 | O625: 0.12936137 | P625: 34.739 | Q625: 28.494 | R625: 2.175 | S625: 0 | T625: 31.654 | U625: 0.419 | V625: =IF(Energy_data_1990___2020[[#This Row],[CO2 emissions from fuel combustion (MtCO2)]]>Energy_data_1990___2020[[#Totals],[CO2 emissions from fuel combustion (MtCO2)]],"Above Average","") | W625: =SUM(Energy_data_1990___2020[[#This Row],[Coal and lignite production (Mt)]]-Energy_data_1990___2020[[#This Row],[Coal and lignite domestic consumption (Mt)]]) -> -1.756
A626: Malaysia | B626: 1994 | C626: Asia & Pacific | D626: 75.333748 | E626: 2.3862985 | F626: 0.28304676 | G626: 57.354935 | H626: 31.56929 | I626: 16.685422 | J626: 15.258342 | K626: 15.179 | L626: 14.404 | M626: 25.468985 | N626: 14.771992 | O626: 0.11861331 | P626: 39.1 | Q626: 34.098 | R626: 2.416 | S626: 0 | T626: 32.794 | U626: 0.141 | V626: =IF(Energy_data_1990___2020[[#This Row],[CO2 emissions from fuel combustion (MtCO2)]]>Energy_data_1990___2020[[#Totals],[CO2 emissions from fuel combustion (MtCO2)]],"Above Average","") | W626: =SUM(Energy_data_1990___2020[[#This Row],[Coal and lignite production (Mt)]]-Energy_data_1990___2020[[#This Row],[Coal and lignite domestic consumption (Mt)]]) -> -2.275
A627: Malaysia | B627: 1995 | C627: Asia & Pacific | D627: 82.462205 | E627: 2.4049058 | F627: 0.28210202 | G627: 63.777437 | H627: 34.289162 | I627: 13.686155 | J627: 15.384078 | K627: 17.54 | L627: 18.075 | M627: 29.178998 | N627: 14.478996 | O627: 0.11730273 | P627: 45.462 | Q627: 39.251 | R627: 2.647 | S627: 0 | T627: 35.977 | U627: 0.135 | V627: =IF(Energy_data_1990___2020[[#This Row],[CO2 emissions from fuel combustion (MtCO2)]]>Energy_data_1990___2020[[#Totals],[CO2 emissions from fuel combustion (MtCO2)]],"Above Average","") | W627: =SUM(Energy_data_1990___2020[[#This Row],[Coal and lignite production (Mt)]]-Energy_data_1990___2020[[#This Row],[Coal and lignite domestic consumption (Mt)]]) -> -2.512
A628: Malaysia | B628: 1996 | C628: Asia & Pacific | D628: 92.92935 | E628: 2.4460712 | F628: 0.28900197 | G628: 69.839394 | H628: 37.99127 | I628: 10.088299 | J628: 15.864093 | K628: 18.629 | L628: 19.192 | M628: 36.382996 | N628: 16.51998 | O628: 0.11814945 | P628: 51.416 | Q628: 43.927 | R628: 2.66 | S628: 0 | T628: 35.988 | U628: 0.243 | V628: =IF(Energy_data_1990___2020[[#This Row],[CO2 emissions from fuel combustion (MtCO2)]]>Energy_data_1990___2020[[#Totals],[CO2 emissions from fuel combustion (MtCO2)]],"Above Average","") | W628: =SUM(Energy_data_1990___2020[[#This Row],[Coal and lignite production (Mt)]]-Energy_data_1990___2020[[#This Row],[Coal and lignite domestic consumption (Mt)]]) -> -2.417
A629: Malaysia | B629: 1997 | C629: Asia & Pacific | D629: 100.15757 | E629: 2.2610983 | F629: 0.2902284 | G629: 73.921978 | H629: 44.295982 | I629: 6.6910837 | J629: 17.054973 | K629: 19.853 | L629: 17.39 | M629: 41.430956 | N629: 19.853015 | O629: 0.12835727 | P629: 57.883 | Q629: 50.986 | R629: 2.573 | S629: 0 | T629: 35.935 | U629: 0.243 | V629: =IF(Energy_data_1990___2020[[#This Row],[CO2 emissions from fuel combustion (MtCO2)]]>Energy_data_1990___2020[[#Totals],[CO2 emissions from fuel combustion (MtCO2)]],"Above Average","") | W629: =SUM(Energy_data_1990___2020[[#This Row],[Coal and lignite production (Mt)]]-Energy_data_1990___2020[[#This Row],[Coal and lignite domestic consumption (Mt)]]) -> -2.33
A630: Malaysia | B630: 1998 | C630: Asia & Pacific | D630: 100.2829 | E630: 2.40522 | F630: 0.31367632 | G630: 74.496358 | H630: 41.693857 | I630: 7.9969034 | J630: 18.350738 | K630: 18.493 | L630: 17.798 | M630: 41.881006 | N630: 19.508018 | O630: 0.13041481 | P630: 60.711 | Q630: 53.235 | R630: 2.746 | S630: 0 | T630: 35.976 | U630: 0.35 | V630: =IF(Energy_data_1990___2020[[#This Row],[CO2 emissions from fuel combustion (MtCO2)]]>Energy_data_1990___2020[[#Totals],[CO2 emissions from fuel combustion (MtCO2)]],"Above Average","") | W630: =SUM(Energy_data_1990___2020[[#This Row],[Coal and lignite production (Mt)]]-Energy_data_1990___2020[[#This Row],[Coal and lignite domestic consumption (Mt)]]) -> -2.396
A631: Malaysia | B631: 1999 | C631: Asia & Pacific | D631: 108.61625 | E631: 2.5703157 | F631: 0.32009608 | G631: 72.989623 | H631: 42.257942 | I631: 11.535572 | J631: 17.99009 | K631: 18.763 | L631: 18.68 | M631: 43.424002 | N631: 22.96002 | O631: 0.12453571 | P631: 65.233 | Q631: 55.999 | R631: 3.077 | S631: 0 | T631: 33.077 | U631: 0.276 | V631: =IF(Energy_data_1990___2020[[#This Row],[CO2 emissions from fuel combustion (MtCO2)]]>Energy_data_1990___2020[[#Totals],[CO2 emissions from fuel combustion (MtCO2)]],"Above Average","") | W631: =SUM(Energy_data_1990___2020[[#This Row],[Coal and lignite production (Mt)]]-Energy_data_1990___2020[[#This Row],[Coal and lignite domestic consumption (Mt)]]) -> -2.801
A632: Malaysia | B632: 2000 | C632: Asia & Pacific | D632: 117.99481 | E632: 2.434623 | F632: 0.31943658 | G632: 77.125334 | H632: 48.465333 | I632: 10.05848 | J632: 18.076909 | K632: 19.015 | L632: 21.814 | M632: 50.443982 | N632: 27.271998 | O632: 0.13120577 | P632: 69.255 | Q632: 61.205 | R632: 3.943 | S632: 0 | T632: 31.319 | U632: 0.384 | V632: =IF(Energy_data_1990___2020[[#This Row],[CO2 emissions from fuel combustion (MtCO2)]]>Energy_data_1990___2020[[#Totals],[CO2 emissions from fuel combustion (MtCO2)]],"Above Average","") | W632: =SUM(Energy_data_1990___2020[[#This Row],[Coal and lignite production (Mt)]]-Energy_data_1990___2020[[#This Row],[Coal and lignite domestic consumption (Mt)]]) -> -3.559
A633: Malaysia | B633: 2001 | C633: Asia & Pacific | D633: 123.60051 | E633: 2.4342199 | F633: 0.3328891 | G633: 78.266719 | H633: 50.776231 | I633: 9.929098 | J633: 18.168275 | K633: 19.822 | L633: 23.448 | M633: 49.091979 | N633: 28.767994 | O633: 0.13675391 | P633: 71.084 | Q633: 65.056 | R633: 4.764 | S633: 0 | T633: 33.447 | U633: 0.546 | V633: =IF(Energy_data_1990___2020[[#This Row],[CO2 emissions from fuel combustion (MtCO2)]]>Energy_data_1990___2020[[#Totals],[CO2 emissions from fuel combustion (MtCO2)]],"Above Average","") | W633: =SUM(Energy_data_1990___2020[[#This Row],[Coal and lignite production (Mt)]]-Energy_data_1990___2020[[#This Row],[Coal and lignite domestic consumption (Mt)]]) -> -4.218
... A838: Poland | B838: 2020 | C838: Europe | D838: 278.0328 | E838: 2.8524681 | F838: 0.23594143 | G838: 55.379556 | H838: 97.470956 | I838: 16.670807 | J838: 15.930954 | K838: 28.664367 | L838: 26.690688 | M838: 5.5341418 | N838: 21.531968 | O838: 0.082714836 | P838: 157.55038 | Q838: 144.6543 | R838: 99.767189 | S838: 11.211958 | T838: 1.5222327 | U838: 100.7726 | V838: =IF(Energy_data_1990___2020[[#This Row],[CO2 emissions from fuel combustion (MtCO2)]]>Energy_data_1990___2020[[#Totals],[CO2 emissions from fuel combustion (MtCO2)]],"Above Average","") | W838: =SUM(Energy_data_1990___2020[[#This Row],[Coal and lignite production (Mt)]]-Energy_data_1990___2020[[#This Row],[Coal and lignite domestic consumption (Mt)]]) -> 1.0054062
...

Sheet QUESTION 3
A1: TOTAL(3.1) | C1: AVERAGE(3.2)
A2: =SUM('Energy data 1990 - 2020'!D2:E2) -> 55.369776 | C2: =AVERAGE('Energy data 1990 - 2020'!H2) -> 22.188078
A3: =SUM('Energy data 1990 - 2020'!D3:E3) -> 59.584997 | C3: =AVERAGE('Energy data 1990 - 2020'!H3) -> 23.469959
A4: =SUM('Energy data 1990 - 2020'!D4:E4) -> 59.645947 | C4: =AVERAGE('Energy data 1990 - 2020'!H4) -> 24.024343
A5: =SUM('Energy data 1990 - 2020'!D5:E5) -> 61.654037 | C5: =AVERAGE('Energy data 1990 - 2020'!H5) -> 24.110238
A6: =SUM('Energy data 1990 - 2020'!D6:E6) -> 58.772576 | C6: =AVERAGE('Energy data 1990 - 2020'!H6) -> 23.239627
A7: =SUM('Energy data 1990 - 2020'!D7:E7) -> 59.172496 | C7: =AVERAGE('Energy data 1990 - 2020'!H7) -> 24.247643
A8: =SUM('Energy data 1990 - 2020'!D8:E8) -> 58.55798 | C8: =AVERAGE('Energy data 1990 - 2020'!H8) -> 23.478104
A9: =SUM('Energy data 1990 - 2020'!D9:E9) -> 60.488538 | C9: =AVERAGE('Energy data 1990 - 2020'!H9) -> 24.058809
A10: =SUM('Energy data 1990 - 2020'!D10:E10) -> 61.88387 | C10: =AVERAGE('Energy data 1990 - 2020'!H10) -> 24.898894
A11: =SUM('Energy data 1990 - 2020'!D11:E11) -> 65.62663 | C11: =AVERAGE('Energy data 1990 - 2020'!H11) -> 26.579256
A12: =SUM('Energy data 1990 - 2020'!D12:E12) -> 66.608779 | C12: =AVERAGE('Energy data 1990 - 2020'!H12) -> 26.998921
A13: =SUM('Energy data 1990 - 2020'!D13:E13) -> 68.171693 | C13: =AVERAGE('Energy data 1990 - 2020'!H13) -> 27.053777
... A1365: =SUM('Energy data 1990 - 2020'!D1365:E1365) -> 87.964834 | C1365: =AVERAGE('Energy data 1990 - 2020'!H1365) -> 29.161319

Sheet QUESTION 5
A1: Row Labels | B1: Sum of CO2 emissions from fuel combustion (MtCO2) | C1: Sum of Year
A2: Africa | B2: 12934.148 | C2: 124310
A3: Arab States | B3: 2763.7766 | C3: 62155
A4: Asia & Pacific | B4: 316952.74 | C4: 745860
A5: Europe | B5: 169400.86 | C5: 994480
A6: Middle east | B6: 33825.903 | C6: 310775
A7: North America | B7: 180453.39 | C7: 124310
A8: South/Latin America | B8: 34380.915 | C8: 372930
A9: Grand Total | B9: 750711.74 | C9: 2734820

Sheet Coordinates
A1: Code | B1: Country | C1: latitude | D1: longitude | F1: Lookups
A2: AD | B2: Andorra | C2: 42.546245 | D2: 1.601554 | F2: =SUM(VLOOKUP(C2,A1:D245,3,FALSE),VLOOKUP(D2,A1:D245,4,FALSE)) -> #N/A
A3: AE | B3: United Arab Emirates | C3: 23.424076 | D3: 53.847818 | F3: =SUM(VLOOKUP(C3,A2:D246,3,FALSE),VLOOKUP(D3,A2:D246,4,FALSE)) -> #N/A
A4: AF | B4: Afghanistan | C4: 33.93911 | D4: 67.709953 | F4: =SUM(VLOOKUP(C4,A3:D247,3,FALSE),VLOOKUP(D4,A3:D247,4,FALSE)) -> #N/A
A5: AG | B5: Antigua and Barbuda | C5: 17.060816 | D5: -61.796428 | F5: =SUM(VLOOKUP(C5,A4:D248,3,FALSE),VLOOKUP(D5,A4:D248,4,FALSE)) -> #N/A
A6: AI | B6: Anguilla | C6: 18.220554 | D6: -63.068615 | F6: =SUM(VLOOKUP(C6,A5:D249,3,FALSE),VLOOKUP(D6,A5:D249,4,FALSE)) -> #N/A
A7: AL | B7: Albania | C7: 41.153332 | D7: 20.168331 | F7: =SUM(VLOOKUP(C7,A6:D250,3,FALSE),VLOOKUP(D7,A6:D250,4,FALSE)) -> #N/A
A8: AM | B8: Armenia | C8: 40.069099 | D8: 45.038189 | F8: =SUM(VLOOKUP(C8,A7:D251,3,FALSE),VLOOKUP(D8,A7:D251,4,FALSE)) -> #N/A
A9: AN | B9: Netherlands Antilles | C9: 12.226079 | D9: -69.060087 | F9: =SUM(VLOOKUP(C9,A8:D252,3,FALSE),VLOOKUP(D9,A8:D252,4,FALSE)) -> #N/A
A10: AO | B10: Angola | C10: -11.202692 | D10: 17.873887 | F10: =SUM(VLOOKUP(C10,A9:D253,3,FALSE),VLOOKUP(D10,A9:D253,4,FALSE)) -> #N/A
A11: AQ | B11: Antarctica | C11: -75.250973 | D11: -0.071389 | F11: =SUM(VLOOKUP(C11,A10:D254,3,FALSE),VLOOKUP(D11,A10:D254,4,FALSE)) -> #N/A
A12: AR | B12: Argentina | C12: -38.416097 | D12: -63.616672 | F12: =SUM(VLOOKUP(C12,A11:D255,3,FALSE),VLOOKUP(D12,A11:D255,4,FALSE)) -> #N/A
A13: AS | B13: American Samoa | C13: -14.270972 | D13: -170.13222 | F13: =SUM(VLOOKUP(C13,A12:D256,3,FALSE),VLOOKUP(D13,A12:D256,4,FALSE)) -> #N/A
... A245: ZW | B245: Zimbabwe | C245: -19.015438 | D245: 29.154857 | F245: =SUM(VLOOKUP(C245,A244:D488,3,FALSE),VLOOKUP(D245,A244:D488,4,FALSE)) -> #N/A

Sheet QUESTION 7
A1: country | B1: Year | C1: Region | D1: CO2 emissions from fuel combustion (MtCO2) | E1: Average CO2 emission factor (tCO2/toe) | F1: CO2 intensity at constant purchasing power parities (kCO2/$15p) | G1: Total energy production (Mtoe) | H1: Total energy consumption (Mtoe) | I1: Share of renewables in electricity production (%) | J1: Share of electricity in total final energy consumption (%) | K1: Oil products domestic consumption (Mt) | L1: Refined oil products production (Mt) | M1: Natural gas production (bcm) | N1: Natural gas domestic consumption (bcm) | O1: Energy intensity of GDP at constant purchasing power parities (koe/$15p) | P1: Electricity production (TWh) | Q1: Electricity domestic consumption (TWh) | R1: Coal and lignite domestic consumption (Mt) | S1: Share of wind and solar in electricity production (%) | T1: Crude oil production (Mt) | U1: Coal and lignite production (Mt) | V1: AVERAGE(4.1) | W1: SURPLUS(4.2)
A2: Algeria | B2: 1990 | C2: Arab States | D2: 52.981921 | E2: 2.3878553 | F2: 0.22888934 | G2: 100.11275 | H2: 22.188078 | I2: 0.78297181 | J2: 8.3765921 | K2: 8.08 | L2: 25.395 | M2: 45.684035 | N2: 14.301991 | O2: 0.095855614 | P2: 17.242 | Q2: 13.693 | R2: 0.94 | S2: 0 | T2: 57.85 | U2: 0 | V2: =IF(#REF!>#REF!,"Above Average","") | W2: =SUM(#REF!-#REF!) -> -0.94
A3: Argentina | B3: 1990 | C3: South/Latin America | D3: 93.453461 | E3: 2.129761 | F3: 0.24215048 | G3: 47.107338 | H3: 43.879788 | I3: 35.819579 | J3: 11.628868 | K3: 18.37 | L3: 23.586 | M3: 18.628006 | N3: 20.570994 | O3: 0.11369843 | P3: 51.014 | Q3: 40.464 | R3: 1.3040155 | S3: 0 | T3: 26.319 | U3: 0.274 | V3: =IF(#REF!>#REF!,"Above Average","") | W3: =SUM(#REF!-#REF!) -> -1.0300155
A4: Australia | B4: 1990 | C4: Asia & Pacific | D4: 261.38502 | E4: 3.034218 | F4: 0.5076514 | G4: 157.52584 | H4: 86.145761 | I4: 10.082635 | J4: 19.270761 | K4: 31.086 | L4: 32.782 | M4: 20.475013 | N4: 17.683994 | O4: 0.16730881 | P4: 155.019 | Q4: 134.339 | R4: 94.1 | S4: 0 | T4: 27.493 | U4: 204.562 | V4: =IF(#REF!>#REF!,"Above Average","") | W4: =SUM(#REF!-#REF!) -> 110.462
A5: Belgium | B5: 1990 | C5: Europe | D5: 106.44542 | E5: 2.2227658 | F5: 0.32184878 | G5: 13.10412 | H5: 47.888723 | I5: 1.6722361 | J5: 14.702905 | K5: 17.597 | L5: 29.37 | M5: 0.012 | N5: 9.6082977 | O5: 0.14479653 | P5: 70.923 | Q5: 59.108 | R5: 16.620146 | S5: 0.009869859 | T5: 0 | U5: 0 | V5: =IF(#REF!>#REF!,"Above Average","") | W5: =SUM(#REF!-#REF!) -> -16.620146
A6: Brazil | B6: 1990 | C6: South/Latin America | D6: 193.76575 | E6: 1.3773719 | F6: 0.12628652 | G6: 104.59321 | H6: 140.67788 | I6: 94.500518 | J6: 15.867493 | K6: 57.32 | L6: 61.121 | M6: 3.9289981 | N6: 3.9719978 | O6: 0.091686578 | P6: 222.821 | Q6: 215.795 | R6: 15.374 | S6: 0 | T6: 32.724 | U6: 4.595 | V6: =IF(#REF!>#REF!,"Above Average","") | W6: =SUM(#REF!-#REF!) -> -10.779
A7: Canada | B7: 1990 | C7: North America | D7: 429.73181 | E7: 1.4397303 | F7: 0.36726676 | G7: 276.26049 | H7: 211.06461 | I7: 62.38738 | J7: 22.715224 | K7: 76.727 | L7: 84.929 | M7: 109.07091 | N7: 67.318932 | O7: 0.25509413 | P7: 482.152 | Q7: 441.314 | R7: 49.373 | S7: 0.00539249 | T7: 91.61 | U7: 68.332 | V7: =IF(#REF!>#REF!,"Above Average","") -> Above Average | W7: =SUM(#REF!-#REF!) -> 18.959
A8: Chile | B8: 1990 | C8: South/Latin America | D8: 30.95435 | E8: 2.209364 | F8: 0.25502996 | G8: 7.9288174 | H8: 14.010525 | I8: 53.837361 | J8: 11.837734 | K8: 6.214 | L8: 6.345 | M8: 1.6790012 | N8: 1.3600004 | O8: 0.11543139 | P8: 18.372 | Q8: 15.811 | R8: 3.7413297 | S8: 0 | T8: 1.102 | U8: 2.183 | V8: =IF(#REF!>#REF!,"Above Average","") | W8: =SUM(#REF!-#REF!) -> -1.5583297
A9: China | B9: 1990 | C9: Asia & Pacific | D9: 2255.3939 | E9: 2.5800499 | F9: 1.3670783 | G9: 880.92627 | H9: 874.16677 | I9: 20.40794 | J9: 5.5818279 | K9: 142.885 | L9: 146.419 | M9: 15.299992 | N9: 15.870011 | O9: 0.52986506 | P9: 621.268 | Q9: 507.054 | R9: 1004.809 | S9: 0.010945357 | T9: 138.306 | U9: 1039.82 | V9: =IF(#REF!>#REF!,"Above Average","") -> Above Average | W9: =SUM(#REF!-#REF!) -> 35.01102
A10: Colombia | B10: 1990 | C10: South/Latin America | D10: 46.10629 | E10: 1.9032818 | F10: 0.17007186 | G10: 48.181292 | H10: 24.224626 | I10: 76.38419 | J10: 12.120017 | K10: 8.112 | L10: 11.101 | M10: 4.5370049 | N10: 4.3260038 | O10: 0.089357162 | P10: 36.357 | Q10: 26.866 | R10: 5.055 | S10: 0 | T10: 22.824 | U10: 21.375 | V10: =IF(#REF!>#REF!,"Above Average","") | W10: =SUM(#REF!-#REF!) -> 16.32
A11: Czechia | B11: 1990 | C11: Europe | D11: 147.40094 | E11: 2.9602859 | F11: 0.64715123 | G11: 41.166023 | H11: 49.792804 | I11: 2.3162135 | J11: 12.079406 | K11: 8.817 | L11: 7.948 | M11: 0.26200003 | N11: 6.5729948 | O11: 0.21861106 | P11: 62.559 | Q11: 53.037 | R11: 84.788 | S11: 0 | T11: 0.22 | U11: 101.398 | V11: =IF(#REF!>#REF!,"Above Average","") | W11: =SUM(#REF!-#REF!) -> 16.61
A12: Egypt | B12: 1990 | C12: Middle east | D12: 78.403283 | E12: 2.3718349 | F12: 0.2136314 | G12: 55.672725 | H12: 33.055962 | I12: 23.504354 | J12: 13.144622 | K12: 20.523 | L12: 24.045 | M12: 8.242 | N12: 8.2420064 | O12: 0.090070096 | P12: 42.256 | Q12: 36.202 | R12: 1.199 | S12: 0 | T12: 45.499 | U12: 0 | V12: =IF(#REF!>#REF!,"Above Average","") | W12: =SUM(#REF!-#REF!) -> -1.199
A13: France | B13: 1990 | C13: Europe | D13: 365.43101 | E13: 1.6265241 | F13: 0.19733883 | G13: 111.90219 | H13: 224.66991 | I13: 14.101214 | J13: 17.979951 | K13: 80.46 | L13: 78.478 | M13: 2.8570034 | N13: 28.231983 | O13: 0.12132549 | P13: 420.751 | Q13: 323.252 | R13: 31.208986 | S13: 0.11954814 | T13: 3.47 | U13: 0 | V13: =IF(#REF!>#REF!,"Above Average","") | W13: =SUM(#REF!-#REF!) -> -31.208986
... A20: Kazakhstan | B20: 1990 | C20: Asia & Pacific | D20: 236.28234 | E20: 3.2168031 | F20: 1.0265633 | G20: 90.977383 | H20: 73.452536 | I20: 8.4299431 | J20: 13.92139 | K20: 19.167 | L20: 18.303 | M20: 7.1140053 | N20: 13.182985 | O20: 0.31912532 | P20: 87.379 | Q20: 96.535 | R20: 90.361 | S20: 0 | T20: 25.82 | U20: 131.443 | V20: =IF(#REF!>#REF!,"Above Average","") | W20: =SUM(#REF!-#REF!) -> 41.082
A21: Kuwait | B21: 1990 | C21: Middle east | D21: 27.83656 | E21: 3.080057 | F21: 0.52351034 | G21: 50.373797 | H21: 9.0376769 | I21: 0 | J21: 20.888641 | K21: 3.8 | L21: 13.274 | M21: 4.0280029 | N21: 6.0279931 | O21: 0.16996775 | P21: 18.477 | Q21: 14.272 | S21: 0 | T21: 46.337 | V21: =IF(#REF!>#REF!,"Above Average","") | W21: =SUM(#REF!-#REF!) -> 0
A22: Malaysia | B22: 1990 | C22: Asia & Pacific | D22: 50.73806 | E22: 2.3919224 | F22: 0.27290635 | G22: 47.749219 | H22: 21.212252 | I22: 17.331422 | J22: 12.797935 | K22: 12.077 | L22: 10.086 | M22: 18.356009 | N22: 8.1840046 | O22: 0.11409499 | P22: 23.016 | Q22: 19.945 | R22: 2.104 | S22: 0 | T22: 30.029 | U22: 0.111 | V22: =IF(#REF!>#REF!,"Above Average","") | W22: =SUM(#REF!-#REF!) -> -1.993
A23: Mexico | B23: 1990 | C23: South/Latin America | D23: 264.6537 | E23: 2.1397182 | F23: 0.22214228 | G23: 195.53812 | H23: 123.68624 | I23: 24.693319 | J23: 10.231723 | K23: 68.6 | L23: 72.169 | M23: 25.57899 | N23: 25.996023 | O23: 0.10381847 | P23: 115.837 | Q23: 100.194 | R23: 7.496 | S23: 4.4251837 | T23: 150.776 | U23: 6.933 | V23: =IF(#REF!>#REF!,"Above Average","") | W23: =SUM(#REF!-#REF!) -> -0.563
A24: Netherlands | B24: 1990 | C24: Europe | D24: 163.33853 | E24: 2.4555345 | F24: 0.31553527 | G24: 60.561183 | H24: 66.518524 | I24: 1.1199422 | J24: 11.217871 | K24: 21.439 | L24: 49.08 | M24: 76.087075 | N24: 44.164947 | O24: 0.12849963 | P24: 71.968 | Q24: 74.074 | R24: 12.528968 | S24: 0.31958648 | T24: 4.076 | U24: 0 | V24: =IF(#REF!>#REF!,"Above Average","") | W24: =SUM(#REF!-#REF!) -> -12.528968
A25: New Zealand | B25: 1990 | C25: Asia & Pacific | D25: 21.620523 | E25: 1.5853812 | F25: 0.25355904 | G25: 12.331681 | H25: 13.637429 | I25: 80.008678 | J25: 24.512203 | K25: 4.149 | L25: 4.863 | M25: 4.9100034 | N25: 4.8880007 | O25: 0.15993569 | P25: 32.264 | Q25: 28.871 | R25: 2.3221237 | S25: 6.8125465 | T25: 2.541 | U25: 2.578 | V25: =IF(#REF!>#REF!,"Above Average","") | W25: =SUM(#REF!-#REF!) -> 0.25587628
A26: Nigeria | B26: 1990 | C26: Africa | D26: 28.320678 | E26: 0.42630721 | F26: 0.092771676 | G26: 146.30308 | H26: 66.432558 | I26: 32.585605 | J26: 1.1411292 | K26: 7.086 | L26: 12.849 | M26: 4 | N26: 4 | O26: 0.21761695 | P26: 13.463 | Q26: 7.871 | R26: 0.075 | S26: 0 | T26: 88.322 | U26: 0.09 | V26: =IF(#REF!>#REF!,"Above Average","") | W26: =SUM(#REF!-#REF!) -> 0.015
A27: Norway | B27: 1990 | C27: Europe | D27: 27.879812 | E27: 1.32301 | F27: 0.16271897 | G27: 119.48311 | H27: 21.073017 | I27: 99.792364 | J27: 47.587183 | K27: 8.05 | L27: 13.767 | M27: 27.641981 | N27: 2.2619976 | O27: 0.12299149 | P27: 121.848 | Q27: 97.698 | R27: 1.277 | S27: 0.053345151 | T27: 82.088 | U27: 0.303 | V27: =IF(#REF!>#REF!,"Above Average","") | W27: =SUM(#REF!-#REF!) -> -0.974
A28: Poland | B28: 1990 | C28: Europe | D28: 355.72662 | E28: 3.4499982 | F28: 0.85589651 | G28: 103.87946 | H28: 103.10922 | I28: 2.4708204 | J28: 12.970721 | K28: 12.885 | L28: 12.812 | M28: 4.0949962 | N28: 12.096014 | O28: 0.24808607 | P28: 136.311 | Q28: 109.195 | R28: 183.63868 | S28: 0 | T28: 0.178 | U28: 215.32 | V28: =IF(#REF!>#REF!,"Above Average","") | W28: =SUM(#REF!-#REF!) -> 31.681319
A29: Portugal | B29: 1990 | C29: Europe | D29: 39.787808 | E29: 2.3710201 | F29: 0.17745326 | G29: 3.392967 | H29: 16.780881 | I29: 35.079471 | J29: 15.046364 | K29: 10.94 | L29: 11.428 | N29: 0 | O29: 0.074842579 | P29: 28.501 | Q29: 23.95 | R29: 4.399 | S29: 0.021051893 | T29: 0 | U29: 0 | V29: =IF(#REF!>#REF!,"Above Average","") | W29: =SUM(#REF!-#REF!) -> -4.399
A30: Romania | B30: 1990 | C30: Europe | D30: 163.01396 | E30: 2.6300111 | F30: 0.58643184 | G30: 40.456423 | H30: 61.982235 | I30: 17.744017 | J30: 10.487675 | K30: 17.032 | L30: 22.618 | M30: 28.336014 | N30: 35.667968 | O30: 0.22297695 | P30: 64.309 | Q30: 60.216 | R30: 46.953 | S30: 0 | T30: 7.929 | U30: 38.183 | V30: =IF(#REF!>#REF!,"Above Average","") | W30: =SUM(#REF!-#REF!) -> -8.77
A31: Russia | B31: 1990 | C31: Europe | D31: 2189.0862 | E31: 2.4909406 | F31: 0.72400579 | G31: 1292.7684 | H31: 878.81909 | I31: 15.338141 | J31: 11.266253 | K31: 213.74 | L31: 267.723 | M31: 628.89239 | N31: 471.54946 | O31: 0.29065558 | P31: 1082.152 | Q31: 917.409 | R31: 388.194 | S31: 0.002587437 | T31: 523.679 | U31: 376.613 | V31: =IF(#REF!>#REF!,"Above Average","") -> Above Average | W31: =SUM(#REF!-#REF!) -> -11.581
A32: Saudi Arabia | B32: 1990 | C32: Middle east | D32: 155.69988 | E32: 2.6840298 | F32: 0.23527478 | G32: 368.44259 | H32: 58.009743 | I32: 0 | J32: 11.963677 | K32: 34.342 | L32: 89.818 | M32: 23.855972 | N32: 23.855972 | O32: 0.087657289 | P32: 69.208 | Q32: 63.633 | R32: 0 | S32: 0 | T32: 341.817 | V32: =IF(#REF!>#REF!,"Above Average","") | W32: =SUM(#REF!-#REF!) -> 0
A33: South Africa | B33: 1990 | C33: Africa | D33: 251.94434 | E33: 2.8082463 | F33: 0.66530894 | G33: 114.53651 | H33: 89.715897 | I33: 1.7048784 | J33: 23.03476 | K33: 15.277 | L33: 13.083 | M33: 1.8419986 | N33: 1.8419986 | O33: 0.2369126 | P33: 167.226 | Q33: 140.711 | R33: 134.175 | S33: 0 | T33: 4.468 | U33: 174.8 | V33: =IF(#REF!>#REF!,"Above Average","") | W33: =SUM(#REF!-#REF!) -> 40.625
A34: South Korea | B34: 1990 | C34: Asia & Pacific | D34: 243.49722 | E34: 2.5913267 | F34: 0.46666676 | G34: 23.675366 | H34: 93.966238 | I34: 6.0377144 | J34: 11.589678 | K34: 48.315 | L34: 42.365 | M34: 0 | N34: 3.0419989 | O34: 0.18008797 | P34: 105.371 | Q34: 94.384 | R34: 44.776 | S34: 0.000949028 | T34: 0 | U34: 17.217 | V34: =IF(#REF!>#REF!,"Above Average","") | W34: =SUM(#REF!-#REF!) -> -27.559
A35: Spain | B35: 1990 | C35: Europe | D35: 205.49384 | E35: 2.280856 | F35: 0.20550057 | G35: 34.612671 | H35: 90.09505 | I35: 17.606946 | J35: 17.554089 | K35: 43.5 | L35: 53.084 | M35: 1.4709988 | N35: 5.7419997 | O35: 0.090098001 | P35: 151.923 | Q35: 129.161 | R35: 47.563 | S35: 0.015139248 | T35: 1.144 | U35: 0 | V35: =IF(#REF!>#REF!,"Above Average","") | W35: =SUM(#REF!-#REF!) -> -47.563
A36: Sweden | B36: 1990 | C36: Europe | D36: 52.57904 | E36: 1.1139784 | F36: 0.18792021 | G36: 29.685656 | H36: 47.199334 | I36: 51.177362 | J36: 31.718375 | K36: 14.669 | L36: 18.044 | N36: 0.61599935 | O36: 0.16869286 | P36: 146.514 | Q36: 130.737 | R36: 4.878 | S36: 0.004095172 | T36: 0 | U36: 0.592 | V36: =IF(#REF!>#REF!,"Above Average","") | W36: =SUM(#REF!-#REF!) -> -4.286
A37: Taiwan | B37: 1990 | C37: Asia & Pacific | D37: 112.39576 | E37: 2.3611967 | F37: 0.6715072 | G37: 10.632471 | H37: 47.601187 | I37: 9.0804279 | J37: 21.513243 | K37: 24.734 | L37: 21.46 | M37: 1.2899989 | N37: 1.7239982 | O37: 0.28439275 | P37: 90.205 | Q37: 78.81 | R37: 17.364769 | S37: 0 | T37: 0.175 | U37: 0 | V37: =IF(#REF!>#REF!,"Above Average","") | W37: =SUM(#REF!-#REF!) -> -17.364769
A38: Thailand | B38: 1990 | C38: Asia & Pacific | D38: 80.922699 | E38: 1.9185734 | F38: 0.20736036 | G38: 26.810361 | H38: 42.178578 | I38: 11.264035 | J38: 11.385808 | K38: 17.207 | L38: 11.86 | M38: 6.3840065 | N38: 6.3869961 | O38: 0.10808049 | P38: 44.176 | Q38: 38.344 | R38: 12.78 | S38: 0.002263673 | T38: 2.751 | U38: 12.421 | V38: =IF(#REF!>#REF!,"Above Average","") | W38: =SUM(#REF!-#REF!) -> -0.359
A39: Turkey | B39: 1990 | C39: Europe | D39: 132.52911 | E39: 2.5761207 | F39: 0.19612622 | G39: 24.834297 | H39: 51.445225 | I39: 40.366335 | J39: 9.3000182 | K39: 22.432 | L39: 22.884 | M39: 0.21199993 | N39: 3.4679992 | O39: 0.076132388 | P39: 57.543 | Q39: 46.82 | R39: 54.451 | S39: 0.13902647 | T39: 3.712 | U39: 47.428 | V39: =IF(#REF!>#REF!,"Above Average","") | W39: =SUM(#REF!-#REF!) -> -7.023
A40: Ukraine | B40: 1990 | C40: Europe | D40: 690.21749 | E40: 2.7384662 | F40: 0.9437469 | G40: 135.79804 | H40: 252.04529 | I40: 3.5882678 | J40: 11.017458 | K40: 66.852 | L40: 61.648 | M40: 27.885991 | N40: 113.34304 | O40: 0.34462609 | P40: 298.835 | Q40: 229.737 | R40: 149.853 | S40: 0 | T40: 5.252 | U40: 159.213 | V40: =IF(#REF!>#REF!,"Above Average","") -> Above Average | W40: =SUM(#REF!-#REF!) -> 9.36
A41: United Arab Emirates | B41: 1990 | C41: Middle east | D41: 52.123659 | E41: 2.5565319 | F41: 0.25932364 | G41: 110.20267 | H41: 20.388425 | I41: 0 | J41: 7.6200285 | K41: 6.326 | L41: 10.316 | M41: 20.11 | N41: 16.91 | O41: 0.10143571 | P41: 17.08 | Q41: 14.347 | R41: 0 | S41: 0 | T41: 91.693 | V41: =IF(#REF!>#REF!,"Above Average","") | W41: =SUM(#REF!-#REF!) -> 0
A42: United Kingdom | B42: 1990 | C42: Europe | D42: 556.16238 | E42: 2.7002799 | F42: 0.33819176 | G42: 208.00914 | H42: 205.96472 | I42: 2.4373157 | J42: 16.756397 | K42: 73.429 | L42: 88.736 | M42: 49.671941 | N42: 58.311941 | O42: 0.12524323 | P42: 319.737 | Q42: 284.416 | R42: 106.681 | S42: 0.002814813 | T42: 91.602 | U42: 92.762 | V42: =IF(#REF!>#REF!,"Above Average","") -> Above Average | W42: =SUM(#REF!-#REF!) -> -13.919
A43: United States | B43: 1990 | C43: North America | D43: 4866.1916 | E43: 2.5478146 | F43: 0.49584284 | G43: 1647.3794 | H43: 1909.9473 | I43: 11.963167 | J43: 17.412043 | K43: 732.07022 | L43: 754.587 | M43: 506.60402 | N43: 534.03916 | O43: 0.19461496 | P43: 3218.621 | Q43: 2712.555 | R43: 819.284 | S43: 0.61343041 | T43: 413.344 | U43: 933.561 | V43: =IF(#REF!>#REF!,"Above Average","") -> Above Average | W43: =SUM(#REF!-#REF!) -> 114.277
A44: Uzbekistan | B44: 1990 | C44: Asia & Pacific | D44: 119.24413 | E44: 2.5160792 | F44: 1.632823 | G44: 38.655248 | H44: 47.392838 | I44: 11.802929 | J44: 10.267496 | K44: 10.956 | L44: 7.89 | M44: 40.728986 | N44: 40.091989 | O44: 0.64895533 | P44: 56.325 | Q44: 45.62 | R44: 8.94 | T44: 2.8 | U44: 6.4 | V44: =IF(#REF!>#REF!,"Above Average","") | W44: =SUM(#REF!-#REF!) -> -2.54
A45: Venezuela | B45: 1990 | C45: South/Latin America | D45: 93.590391 | E45: 2.3629933 | F45: 0.30540731 | G45: 144.84382 | H45: 39.606711 | I45: 62.343858 | J45: 14.881083 | K45: 17.714 | L45: 50.537 | M45: 17.556015 | N45: 16.772984 | O45: 0.12924595 | P45: 59.321 | Q45: 47.148 | R45: 0.646 | S45: 0 | T45: 115.187 | U45: 2.189 | V45: =IF(#REF!>#REF!,"Above Average","") | W45: =SUM(#REF!-#REF!) -> 1.543
D46: =AVERAGE(#REF!) -> 420.39206

Sheet QUESTION 8
A1: Row Labels | B1: Sum of Total energy production (Mtoe)
A2: Africa | B2: 11232.908
A3: Arab States | B3: 4305.54
A4: Asia & Pacific | B4: 98672.243
A5: Europe | B5: 70568.859
A6: Middle east | B6: 37309.039
A7: North America | B7: 67488.007
A8: South/Latin America | B8: 23907.312
A9: Grand Total | B9: 313483.91
